Workbook
Name Driveway: 'Repair Estimator'!$J$10:$J$14
Name Landscape: 'Repair Estimator'!$J$10:$J$15
Name Landscaping: 'Repair Estimator'!$J$10:$J$15

Sheet Directions and Notes
A1: DIRECTIONS
A3: Step One
A4: Fill out all the items in the "Property Details" and the "Income and Expenses" tab.
A5: • You will fill in all items that are in gray cells.
A6: • You won't ever touch the yellow cells because they will autopopulate.
A7: Note: On the "Property Details" tab, the sheet works whether you use either type of financing, both, or none (i.e., cash deal)
A8: Note: Use the "Repair Estimator" tab to help calculate rehab expenses
A10: Step Two
A11: Go to the "Deal Calculations" tab to review the analysis of your property.
A12: • All the input you have provided from the "Property Details" sheet and the "Income and Expenses" sheet will autocalculate in the "Deal Calculations" sheet.
A14: Step Three
A15: Long-term funding (this is common with turn-key purchases)
... A1016: STILL NEEDED: seller price; 24mo earnings + Schedule E + booking ledger; actual cleaning fee; sq ft/county record; STR permit transferability (Village of Bourbonnais); title search.

Sheet Property Details
A1: Property Details
A2: Address: 423 S Rivard St, Bourbonnais IL â€” ACTUALS Oct 2025-Oct 2026, bank loan 8% (off-market; Airbnb #36696033, 4.95x374 Guest Favorite, Top 10%)
A3: Bed/Bath: 2/1 (sleeps 6; king + queen + air bed)
A4: Sq Ft: TBD (county record pending)
A5: Property Details
A6: Purchase Price | B6: 200000
A7: Closing Costs | B7: 0
A8: After Repair Value | B8: 200000
A9: Annual Property Taxes | B9: 3170
A10: Annual Insurance | B10: 1800
A11: Repair Costs | B11: 0
A12: Furnishing Costs | B12: 0
A14: Conventional / Asset-Based Loan
A15: Loan to Value Percentage | B15: 0.8
A16: Loan Amount | B16: =SUM(B6*B15) -> 160000
A17: Rehab Funding | B17: 0
A18: Down Payment Amount | B18: =SUM(B6-B16) -> 40000
A19: Loan Amount | B19: =SUM(B16,B17) -> 160000
A20: Loan Term (Years) | B20: 30
A21: Loan APR | B21: 0.08
A22: PMI | B22: 0
A24: Private Loan (Interest Only)
A25: Private Loan Amount | B25: 0
A26: Private Loan ARP | B26: 0.1

Sheet Income and Expenses
A2: Income/Expense Calculations
A4: Address: 423 S Rivard St, Bourbonnais IL â€” ACTUALS Oct 2025-Oct 2026, bank loan 8% (off-market; Airbnb #36696033, 4.95x374 Guest Favorite, Top 10%)
A6: INCOME
B7: High Season | C7: Low Season | D7: Total
A8: Average Daily Rate Unit 1 | B8: 125.97144 | C8: 125.97144 | D8: =SUM(B8:C8)/2 -> 125.97144
A9: Average Daily Rate Unit 2 | B9: 0 | C9: 0 | D9: =SUM(B9:C9)/2 -> 0
A10: Average Daily Rate Unit 3 | B10: 0 | C10: 0 | D10: =SUM(B10:C10)/2 -> 0
A11: Average Daily Rate Unit 4 | B11: 0 | C11: 0 | D11: =SUM(B11:C11)/2 -> 0
A12: TOTAL | B12: =SUM(B8:B11) -> 125.97144 | C12: =SUM(C8:C11) -> 125.97144 | D12: =SUM(D8:D11) -> 125.97144
A13: Occupancy % | B13: 0.72054795 | C13: 0.72054795 | D13: =SUM(B13*B15)+(C13*C15) -> 0.72054795
A14: Days Listed Each Season | B14: 182.5 | C14: =SUM(D14-B14) -> 182.5 | D14: 365
A15: Season % of Year | B15: 0.5 | C15: 0.5 | D15: =SUM(B15+C15) -> 1
A16: Annual Income Total | B16: =SUM(B12*B13*B14) -> 16565.245 | C16: =SUM(C12*C13*C14) -> 16565.245 | D16: =SUM(B16:C16) -> 33130.49
A17: Monthly Income Total | B17: =SUM(B16)/(B15*12) -> 2760.8742 | C17: =SUM(C16)/(C15*12) -> 2760.8742 | D17: =SUM(D16/12) -> 2760.8742
A19: Cleaning Fee Charged | B19: 100
A20: Amount Paid to Cleaner | B20: 100 | Z20: =SUM(B20*AA23) -> 8400
A21: Cleanings/Month High Season | B21: 6.9041096 | Z21: =SUM(B14/30) -> 6.0833333 | AA21: =SUM(Z21*B21) -> 42
A22: Cleanings/Month Low Seasons | B22: 6.9041096 | Z22: =SUM(C14/30) -> 6.0833333 | AA22: =SUM(Z22*B22) -> 42
A23: Cleaning Income Total | B23: =SUM(B19*AA23) -> 8400 | AA23: =SUM(AA21:AA22) -> 84
A25: Total Annual Gross Income | B25: =SUM(B23,D16) -> 41530.49
A26: Total Monthly Gross Income | B26: =SUM(B25/12) -> 3460.8742
A28: Monthly Average Expenses
A29: Conventional/Asset Based Mortgage | B29: =PMT('Property Details'!B21/12,'Property Details'!B20*12,'Property Details'!B19)-'Property Details'!B22 -> -1174.0233
A30: Private Loan (Interest Only) | B30: =SUM('Property Details'!B25*'Property Details'!B26/-12) -> 0
A31: Insurance | B31: =SUM('Property Details'!B10/-12) -> -150
A32: Property Taxes | B32: =SUM('Property Details'!B9/-12) -> -264.16667
A33: Cleaning | B33: =SUM(Z20/-12) -> -700
A34: Utilities/WIFI | B34: -450
A35: Lawn/Snow Removal | B35: -125
A36: Consumables | B36: -100
A37: Maintenance (AVG 2-5% Income) | B37: -125
A39: Total Monthly Average Expenses | B39: =SUM(B29:B37) -> -3088.19

Sheet Deal Calculations
A1: Deal Calculations
A7: Total Income | B7: ='Income and Expenses'!B25 -> 41530.49
A8: Total Expenses | B8: =SUM('Income and Expenses'!B39*12) -> -37058.28
A9: Total Annual Net Cash Flow | B9: =SUM(B7,B8) -> 4472.2102
A10: Total Average Monthly Net Cash Flow | B10: =SUM(B9/12) -> 372.68418
A11: ROI (from Cash Flow) | B11: =SUM(B9/('Property Details'!B6+'Property Details'!B7+'Property Details'!B11+'Property Details'!B12)) -> 0.022361051
A12: Cash on Cash Return | B12: =SUM('Deal Calculations'!B9/('Property Details'!B6+'Property Details'!B11+'Property Details'!B12+'Property Details'!B7-'Property Details'!B19-'Property Details'!B25)) -> 0.11180525
A13: Equity | B13: =SUM('Property Details'!B8-'Property Details'!B6-'Property Details'!B11-'Property Details'!B12) -> 0

Sheet Refinance Calculations
A1: Refinance Calculations
A7: New Loan Terms
A8: After Repair Value | B8: ='Property Details'!B8 -> 200000
A9: Loan to Value % | B9: 0.8
A10: Loan Amount | B10: =SUM(B8*B9) -> 160000
A11: Closing Costs | B11: 3500
A12: Term (Years) | B12: 30
A13: APR | B13: 0.06
A15: After Refinance Calculations
A16: Your New Payment | B16: =PMT(B13/12,B12*12,B10) -> -959.28084
A17: Your Money Left in Deal | B17: =SUM('Property Details'!B6+'Property Details'!B7+'Property Details'!B11+'Property Details'!B12-'Refinance Calculations'!B10+'Refinance Calculations'!B11) -> 43500
A18: Total Monthly Income | B18: ='Income and Expenses'!B26 -> 3460.8742
A19: Total Monthly Expenses | B19: ='Income and Expenses'!B31+'Income and Expenses'!B32+'Income and Expenses'!B34+'Income and Expenses'!B33+'Income and Expenses'!B36+'Income and Expenses'!B37+'Refinance Calculations'!B16 -> -2748.4475
A20: Monthly Cash Flow | B20: =SUM(B18+B19) -> 712.42666
A21: Annual Cash Flow | B21: =SUM(B20*12) -> 8549.1199
A22: Cash on Cash Return | B22: =SUM(B21/B17) -> 0.19653149

Sheet Repair Estimator
B1: QUICK REPAIR ESTIMATOR
A3: LEAD SOURCE | C3: DATE | E3: ASKING PRICE
A5: PROPERTY ADDRESS | E5: CITY, STATE AND ZIP
A7: VACATION RENTAL OR FLIP | C7: YEAR BUILT | E7: SQ FT
A8: BEDROOMS | C8: BATHS | E8: GARAGE TYPE
A10: Inspection Checklist | B10: Yes | C10: Maybe | D10: No | E10: Repair Cost Calculations | F10: Number | G10: Repair Cost
A11: Exterior
A12: General
A13: Landscaping? | E13: Clean Yard (Easy): $1000 Landscape (Hard): $2500
A14: Driveway Repair? | E14: Seal Coat: $1.50 sq/ft Asphalt: $3.00 sq/ft Concrete: $5.00 sq/ft
A15: Sidewalk Repair? | E15: Concrete: $5.00 sq/ft Pavers: $8.30 sq/ft
A16: Decks/ Porches/ Patios? | E16: Deck Paint (Small): $500 Deck Paint (Large): $1,000 Rebuild: $35.00 sq/ft
A17: Roof Need Repairs? | E17: 1500 sq/ft House - Additional Layer of Shingles: $3500 Rip and Reply: $6000
A18: Gutters, Fascia, Soffit need Repair? | E18: Replace: $2500
A19: Exterior Siding, Paint, or Tuckpoint? | E19: Exterior Paint: $3.00 sq/ft Exterior Siding: $5.00 sq/ft Exterior Tuck Point: $10.00 sq/ft
A20: Windows? | E20: # of Windows x $350 for Standard Installed
A21: Exterior Doors? | E21: $650 Per door Set Standard
A22: Garage
A23: Need a roof? | E23: Rip and Reply ($2,000)
A24: Siding? | E24: Siding ($5.00sq/ft)
A25: Windows? | E25: # of windows x $350 for Standard
A26: Service Door? | E26: Doors ($400)
A27: Overhead Door/ Motor? | E27: 1 Garage Door ($1,000)
A28: Garage Floors need repair? | E28: Concrete Floor: $5.00 sq/ft Expoxy Floor: $3.00 sq/ft
A29: Interior garage walls need paint? | E29: Paint ($3.50 sq/ft)
A30: Garage Electrical/ Fixtures/ GFI's | E30: All $1,500
A31: Interior
A32: General
A33: Interior Paint: Complete | E33: Interior Paint (walls/trim/ceiling): $3.50 sq/ft
A34: Sheetrock damaged or needing repair? | E34: Single Family Patch: $1000 Sheetrock: $4.00 sq/ft Wall Insulation: $2.50 sq/ft
A35: Trim need replacing? | E35: Trim: $3.00/ Linear Ft.
A36: Doors need replacing? | E36: Interior Doors: $175
A37: House need carpet? | E37: Carpet: $2.00 sq/ft
A38: House need tile/ vinyl? | E38: Ceramic Tiles: $5.00 sq/ft Luxury Vinyl Planking (LVP): $3.50
A39: Floors need to be sanded? | E39: Sand and Refinish: $3.00 sq/ft
A40: Hardwood Install? | E40: Hardwood Install: $8.00 sq/ft Engineered Hardwood: $5.50 sq/ft
A41: Kitchen
A42: New Cabinets? | E42: 1500 sq/ft House - Replace: $7500
A43: New Countertops & Backsplash? | E43: 1500 st/ft House - Quartz Countertop: $3000 Subway Tile Backsplash: $2.00 sq/ft
A44: Full Kitchen Remodel? | E44: Full Remodel other than cabinets, counters, and appliances (separate line items): $2,000-4,000
...
